Workbook

Sheet Hoja1
A1: Regression Analysis | J1: Cook's D
A3: OVERALL FIT | J3: Obs | K3: =demanda!D1 -> alumnos_esperando | L3: =demanda!I1 -> tiempo_espera_acum | M3: Pred Y | N3: Residual | O3: Leverage | P3: SResidual | Q3: Mod MSE | R3: RStudent | S3: T-Test | T3: Cook's D | U3: DFFITS
A4: Multiple R | B4: =SQRT(B5) -> 0.38101403 | D4: AIC | E4: =B8*LN(C13/B8)+2*(B12+1) -> 8819.5391 | J4: 1 | K4: =demanda!D2 -> 0 | L4: =demanda!I2 -> 3 | M4: {=TREND(demanda!I2:I1922,demanda!D2:D1922)} -> 14.416809 | N4: =L4-M4 -> -11.416809 | O4: {=[1]!LEVERAGE(demanda!D2:D1922)} -> 0.00074087557 | P4: =N4/SQRT($X$6) -> -1.1503287 | Q4: =($X$6-N4^2/((1-O4)*$X$5))*$X$5/($X$5-1) -> 98.485475 | R4: =N4/SQRT(Q4*(1-O4)) -> -1.1508523 | S4: =_xlfn.T.DIST.2T(ABS(R4),$X$5) -> 0.24993638 | T4: =(N4^2/$X$6)*(O4/(1-O4)^2)/($X$7+1) -> 0.00049091117 | U4: =R4*SQRT(O4/(1-O4)) -> -0.031336693 | W4: SSE | X4: =DEVSQ(N4:N1924) -> 189025.58
A5: R Square | B5: =C12/C14 -> 0.14517169 | D5: AICc | E5: =E4+2*(B12+2)*(B12+3)/(B8-B12-3) -> 8819.5516 | J5: =J4+1 -> 2 | K5: =demanda!D3 -> 5 | L5: =demanda!I3 -> 2 | M5: 1.2636408 | N5: =L5-M5 -> 0.73635917 | O5: 0.0039509249 | P5: =N5/SQRT($X$6) -> 0.074193677 | Q5: =($X$6-N5^2/((1-O5)*$X$5))*$X$5/($X$5-1) -> 98.5532 | R5: =N5/SQRT(Q5*(1-O5)) -> 0.074321414 | S5: =_xlfn.T.DIST.2T(ABS(R5),$X$5) -> 0.94076238 | T5: =(N5^2/$X$6)*(O5/(1-O5)^2)/($X$7+1) -> 1.0960771e-05 | U5: =R5*SQRT(O5/(1-O5)) -> 0.0046808313 | W5: dfE | X5: =COUNT(demanda!I2:I1922)-X7-1 -> 1919
A6: Adjusted R Square | B6: =1-(1-B5)*(B8-1)/(B8-B12-1) -> 0.14472624 | D6: SBC | E6: =B8*LN(C13/B8)+(B12+1)*LN(B8) -> 8830.6603 | J6: =J5+1 -> 3 | K6: =demanda!D4 -> 1 | L6: =demanda!I4 -> 3 | M6: 11.786176 | N6: =L6-M6 -> -8.7861756 | O6: 0.00052058797 | P6: =N6/SQRT($X$6) -> -0.8852727 | Q6: =($X$6-N6^2/((1-O6)*$X$5))*$X$5/($X$5-1) -> 98.513214 | R6: =N6/SQRT(Q6*(1-O6)) -> -0.8854534 | S6: =_xlfn.T.DIST.2T(ABS(R6),$X$5) -> 0.37602308 | T6: =(N6^2/$X$6)*(O6/(1-O6)^2)/($X$7+1) -> 0.00020420698 | U6: =R6*SQRT(O6/(1-O6)) -> -0.020208117 | W6: MSE | X6: =X4/X5 -> 98.502127
A7: Standard Error | B7: =SQRT(D13) -> 9.9248238 | J7: =J6+1 -> 4 | K7: =demanda!D5 -> 0 | L7: =demanda!I5 -> 5 | M7: 14.416809 | N7: =L7-M7 -> -9.4168093 | O7: 0.00074087557 | P7: =N7/SQRT($X$6) -> -0.94881375 | Q7: =($X$6-N7^2/((1-O7)*$X$5))*$X$5/($X$5-1) -> 98.507216 | R7: =N7/SQRT(Q7*(1-O7)) -> -0.94914091 | S7: =_xlfn.T.DIST.2T(ABS(R7),$X$5) -> 0.34266846 | T7: =(N7^2/$X$6)*(O7/(1-O7)^2)/($X$7+1) -> 0.0003339804 | U7: =R7*SQRT(O7/(1-O7)) -> -0.02584427 | W7: k | X7: =COUNT(demanda!D2) -> 1
A8: Observations | B8: =COUNT(demanda!I2:I1922) -> 1921 | J8: =J7+1 -> 5 | K8: =demanda!D6 -> 0 | L8: =demanda!I6 -> 16 | M8: 14.416809 | N8: =L8-M8 -> 1.5831907 | O8: 0.00074087557 | P8: =N8/SQRT($X$6) -> 0.15951827 | Q8: =($X$6-N8^2/((1-O8)*$X$5))*$X$5/($X$5-1) -> 98.552176 | R8: =N8/SQRT(Q8*(1-O8)) -> 0.15953687 | S8: =_xlfn.T.DIST.2T(ABS(R8),$X$5) -> 0.8732627 | T8: =(N8^2/$X$6)*(O8/(1-O8)^2)/($X$7+1) -> 9.4401718e-06 | U8: =R8*SQRT(O8/(1-O8)) -> 0.0043440483
J9: =J8+1 -> 6 | K9: =demanda!D7 -> 2 | L9: =demanda!I7 -> 3 | M9: 9.1555419 | N9: =L9-M9 -> -6.1555419 | O9: 0.0007314491 | P9: =N9/SQRT($X$6) -> -0.62021675 | Q9: =($X$6-N9^2/((1-O9)*$X$5))*$X$5/($X$5-1) -> 98.533714 | R9: =N9/SQRT(Q9*(1-O9)) -> -0.62034424 | S9: =_xlfn.T.DIST.2T(ABS(R9),$X$5) -> 0.53510483 | T9: =(N9^2/$X$6)*(O9/(1-O9)^2)/($X$7+1) -> 0.00014088886 | U9: =R9*SQRT(O9/(1-O9)) -> -0.016783545
A10: ANOVA | E10: Alpha | F10: 0.05 | J10: =J9+1 -> 7 | K10: =demanda!D8 -> 3 | L10: =demanda!I8 -> 4 | M10: 6.5249082 | N10: =L10-M10 -> -2.5249082 | O10: 0.001373459 | P10: =N10/SQRT($X$6) -> -0.25440333 | Q10: =($X$6-N10^2/((1-O10)*$X$5))*$X$5/($X$5-1) -> 98.550155 | R10: =N10/SQRT(Q10*(1-O10)) -> -0.25451617 | S10: =_xlfn.T.DIST.2T(ABS(R10),$X$5) -> 0.79912408 | T10: =(N10^2/$X$6)*(O10/(1-O10)^2)/($X$7+1) -> 4.4568197e-05 | U10: =R10*SQRT(O10/(1-O10)) -> -0.0094389064
B11: df | C11: SS | D11: MS | E11: F | F11: p-value | G11: sig | J11: =J10+1 -> 8 | K11: =demanda!D9 -> 0 | L11: =demanda!I9 -> 10 | M11: 14.416809 | N11: =L11-M11 -> -4.4168093 | O11: 0.00074087557 | P11: =N11/SQRT($X$6) -> -0.44502647 | Q11: =($X$6-N11^2/((1-O11)*$X$5))*$X$5/($X$5-1) -> 98.543305 | R11: =N11/SQRT(Q11*(1-O11)) -> -0.44509839 | S11: =_xlfn.T.DIST.2T(ABS(R11),$X$5) -> 0.65629885 | T11: =(N11^2/$X$6)*(O11/(1-O11)^2)/($X$7+1) -> 7.3473498e-05 | U11: =R11*SQRT(O11/(1-O11)) -> -0.012119637
A12: Regression | B12: =COUNT(demanda!D2) -> 1 | C12: =DEVSQ(MMULT([1]!DESIGN(demanda!D2:D1922),B17:B18)) -> 32101.375 | D12: =C12/B12 -> 32101.375 | E12: =D12/D13 -> 325.89525 | F12: =_xlfn.F.DIST.RT(E12,B12,B13) -> 2.0695829e-67 | G12: =IF(F12<F10,"yes","no") -> yes | J12: =J11+1 -> 9 | K12: =demanda!D10 -> 2 | L12: =demanda!I10 -> 3 | M12: 9.1555419 | N12: =L12-M12 -> -6.1555419 | O12: 0.0007314491 | P12: =N12/SQRT($X$6) -> -0.62021675 | Q12: =($X$6-N12^2/((1-O12)*$X$5))*$X$5/($X$5-1) -> 98.533714 | R12: =N12/SQRT(Q12*(1-O12)) -> -0.62034424 | S12: =_xlfn.T.DIST.2T(ABS(R12),$X$5) -> 0.53510483 | T12: =(N12^2/$X$6)*(O12/(1-O12)^2)/($X$7+1) -> 0.00014088886 | U12: =R12*SQRT(O12/(1-O12)) -> -0.016783545
A13: Residual | B13: =B14-B12 -> 1919 | C13: =C14-C12 -> 189025.58 | D13: =C13/B13 -> 98.502127 | J13: =J12+1 -> 10 | K13: =demanda!D11 -> 1 | L13: =demanda!I11 -> 17 | M13: 11.786176 | N13: =L13-M13 -> 5.2138244 | O13: 0.00052058797 | P13: =N13/SQRT($X$6) -> 0.52533169 | Q13: =($X$6-N13^2/((1-O13)*$X$5))*$X$5/($X$5-1) -> 98.539303 | R13: =N13/SQRT(Q13*(1-O13)) -> 0.52536935 | S13: =_xlfn.T.DIST.2T(ABS(R13),$X$5) -> 0.59938715 | T13: =(N13^2/$X$6)*(O13/(1-O13)^2)/($X$7+1) -> 7.1909061e-05 | U13: =R13*SQRT(O13/(1-O13)) -> 0.011990157
A14: Total | B14: =B8-1 -> 1920 | C14: =DEVSQ(demanda!I2:I1922) -> 221126.96 | J14: =J13+1 -> 11 | K14: =demanda!D12 -> 0 | L14: =demanda!I12 -> 9 | M14: 14.416809 | N14: =L14-M14 -> -5.4168093 | O14: 0.00074087557 | P14: =N14/SQRT($X$6) -> -0.54578393 | Q14: =($X$6-N14^2/((1-O14)*$X$5))*$X$5/($X$5-1) -> 98.538174 | R14: =N14/SQRT(Q14*(1-O14)) -> -0.54588634 | S14: =_xlfn.T.DIST.2T(ABS(R14),$X$5) -> 0.58520752 | T14: =(N14^2/$X$6)*(O14/(1-O14)^2)/($X$7+1) -> 0.00011050973 | U14: =R14*SQRT(O14/(1-O14)) -> -0.014864004
J15: =J14+1 -> 12 | K15: =demanda!D13 -> 0 | L15: =demanda!I13 -> 5 | M15: 14.416809 | N15: =L15-M15 -> -9.4168093 | O15: 0.00074087557 | P15: =N15/SQRT($X$6) -> -0.94881375 | Q15: =($X$6-N15^2/((1-O15)*$X$5))*$X$5/($X$5-1) -> 98.507216 | R15: =N15/SQRT(Q15*(1-O15)) -> -0.94914091 | S15: =_xlfn.T.DIST.2T(ABS(R15),$X$5) -> 0.34266846 | T15: =(N15^2/$X$6)*(O15/(1-O15)^2)/($X$7+1) -> 0.0003339804 | U15: =R15*SQRT(O15/(1-O15)) -> -0.02584427
B16: coeff | C16: std err | D16: t stat | E16: p-value | F16: lower | G16: upper | J16: =J15+1 -> 13 | K16: =demanda!D14 -> 0 | L16: =demanda!I14 -> 35 | M16: 14.416809 | N16: =L16-M16 -> 20.583191 | O16: 0.00074087557 | P16: =N16/SQRT($X$6) -> 2.0739099 | Q16: =($X$6-N16^2/((1-O16)*$X$5))*$X$5/($X$5-1) -> 98.33243 | R16: =N16/SQRT(Q16*(1-O16)) -> 2.076468 | S16: =_xlfn.T.DIST.2T(ABS(R16),$X$5) -> 0.037983496 | T16: =(N16^2/$X$6)*(O16/(1-O16)^2)/($X$7+1) -> 0.0015956544 | U16: =R16*SQRT(O16/(1-O16)) -> 0.056540394
A17: Intercept | B17: {=[1]!RegCoeff(demanda!D2:D1922,demanda!I2:I1922)} -> 14.416809 | C17: 0.27014407 | D17: =B17/C17 -> 53.367113 | E17: =_xlfn.T.DIST.2T(ABS(D17),$B$13) -> 0 | F17: =B17-_xlfn.T.INV.2T(F$10,$B$13)*C17 -> 13.887002 | G17: =B17+_xlfn.T.INV.2T(F$10,$B$13)*C17 -> 14.946616 | J17: =J16+1 -> 14 | K17: =demanda!D15 -> 2 | L17: =demanda!I15 -> 5 | M17: 9.1555419 | N17: =L17-M17 -> -4.1555419 | O17: 0.0007314491 | P17: =N17/SQRT($X$6) -> -0.41870183 | Q17: =($X$6-N17^2/((1-O17)*$X$5))*$X$5/($X$5-1) -> 98.544474 | R17: =N17/SQRT(Q17*(1-O17)) -> -0.41876504 | S17: =_xlfn.T.DIST.2T(ABS(R17),$X$5) -> 0.67543472 | T17: =(N17^2/$X$6)*(O17/(1-O17)^2)/($X$7+1) -> 6.4209516e-05 | U17: =R17*SQRT(O17/(1-O17)) -> -0.011329777
A18: {=TRANSPOSE(demanda!D1)} -> alumnos_esperando | B18: -2.6306337 | C18: 0.14572074 | D18: =B18/C18 -> -18.052569 | E18: =_xlfn.T.DIST.2T(ABS(D18),$B$13) -> 2.0695829e-67 | F18: =B18-_xlfn.T.INV.2T(F$10,$B$13)*C18 -> -2.9164213 | G18: =B18+_xlfn.T.INV.2T(F$10,$B$13)*C18 -> -2.344846 | J18: =J17+1 -> 15 | K18: =demanda!D16 -> 1 | L18: =demanda!I16 -> 2 | M18: 11.786176 | N18: =L18-M18 -> -9.7861756 | O18: 0.00052058797 | P18: =N18/SQRT($X$6) -> -0.98603016 | Q18: =($X$6-N18^2/((1-O18)*$X$5))*$X$5/($X$5-1) -> 98.503526 | R18: =N18/SQRT(Q18*(1-O18)) -> -0.98627992 | S18: =_xlfn.T.DIST.2T(ABS(R18),$X$5) -> 0.32412011 | T18: =(N18^2/$X$6)*(O18/(1-O18)^2)/($X$7+1) -> 0.00025333595 | U18: =R18*SQRT(O18/(1-O18)) -> -0.022509214
J19: =J18+1 -> 16 | K19: =demanda!D17 -> 0 | L19: =demanda!I17 -> 8 | M19: 14.416809 | N19: =L19-M19 -> -6.4168093 | O19: 0.00074087557 | P19: =N19/SQRT($X$6) -> -0.64654138 | Q19: =($X$6-N19^2/((1-O19)*$X$5))*$X$5/($X$5-1) -> 98.532 | R19: =N19/SQRT(Q19*(1-O19)) -> -0.64668297 | S19: =_xlfn.T.DIST.2T(ABS(R19),$X$5) -> 0.51791449 | T19: =(N19^2/$X$6)*(O19/(1-O19)^2)/($X$7+1) -> 0.00015507853 | U19: =R19*SQRT(O19/(1-O19)) -> -0.017608607
A20: Shapiro-Wilk Test | J20: =J19+1 -> 17 | K20: =demanda!D18 -> 0 | L20: =demanda!I18 -> 3 | M20: 14.416809 | N20: =L20-M20 -> -11.416809 | O20: 0.00074087557 | P20: =N20/SQRT($X$6) -> -1.1503287 | Q20: =($X$6-N20^2/((1-O20)*$X$5))*$X$5/($X$5-1) -> 98.485475 | R20: =N20/SQRT(Q20*(1-O20)) -> -1.1508523 | S20: =_xlfn.T.DIST.2T(ABS(R20),$X$5) -> 0.24993638 | T20: =(N20^2/$X$6)*(O20/(1-O20)^2)/($X$7+1) -> 0.00049091117 | U20: =R20*SQRT(O20/(1-O20)) -> -0.031336693
J21: =J20+1 -> 18 | K21: =demanda!D19 -> 2 | L21: =demanda!I19 -> 2 | M21: 9.1555419 | N21: =L21-M21 -> -7.1555419 | O21: 0.0007314491 | P21: =N21/SQRT($X$6) -> -0.7209742 | Q21: =($X$6-N21^2/((1-O21)*$X$5))*$X$5/($X$5-1) -> 98.526769 | R21: =N21/SQRT(Q21*(1-O21)) -> -0.72114783 | S21: =_xlfn.T.DIST.2T(ABS(R21),$X$5) -> 0.47090641 | T21: =(N21^2/$X$6)*(O21/(1-O21)^2)/($X$7+1) -> 0.00019038342 | U21: =R21*SQRT(O21/(1-O21)) -> -0.019510808
B22: =N3 -> Residual | J22: =J21+1 -> 19 | K22: =demanda!D20 -> 0 | L22: =demanda!I20 -> 3 | M22: 14.416809 | N22: =L22-M22 -> -11.416809 | O22: 0.00074087557 | P22: =N22/SQRT($X$6) -> -1.1503287 | Q22: =($X$6-N22^2/((1-O22)*$X$5))*$X$5/($X$5-1) -> 98.485475 | R22: =N22/SQRT(Q22*(1-O22)) -> -1.1508523 | S22: =_xlfn.T.DIST.2T(ABS(R22),$X$5) -> 0.24993638 | T22: =(N22^2/$X$6)*(O22/(1-O22)^2)/($X$7+1) -> 0.00049091117 | U22: =R22*SQRT(O22/(1-O22)) -> -0.031336693
A23: W-stat | B23: =[1]!SHAPIRO(N4:N1924) -> 0.68031108 | J23: =J22+1 -> 20 | K23: =demanda!D21 -> 2 | L23: =demanda!I21 -> 12 | M23: 9.1555419 | N23: =L23-M23 -> 2.8444581 | O23: 0.0007314491 | P23: =N23/SQRT($X$6) -> 0.28660036 | Q23: =($X$6-N23^2/((1-O23)*$X$5))*$X$5/($X$5-1) -> 98.549262 | R23: =N23/SQRT(Q23*(1-O23)) -> 0.28663667 | S23: =_xlfn.T.DIST.2T(ABS(R23),$X$5) -> 0.77442148 | T23: =(N23^2/$X$6)*(O23/(1-O23)^2)/($X$7+1) -> 3.0084524e-05 | U23: =R23*SQRT(O23/(1-O23)) -> 0.0077550158
A24: p-value | B24: =[1]!SWTEST(N4:N1924) -> 0 | J24: =J23+1 -> 21 | K24: =demanda!D22 -> 5 | L24: =demanda!I22 -> 2 | M24: 1.2636408 | N24: =L24-M24 -> 0.73635917 | O24: 0.0039509249 | P24: =N24/SQRT($X$6) -> 0.074193677 | Q24: =($X$6-N24^2/((1-O24)*$X$5))*$X$5/($X$5-1) -> 98.5532 | R24: =N24/SQRT(Q24*(1-O24)) -> 0.074321414 | S24: =_xlfn.T.DIST.2T(ABS(R24),$X$5) -> 0.94076238 | T24: =(N24^2/$X$6)*(O24/(1-O24)^2)/($X$7+1) -> 1.0960771e-05 | U24: =R24*SQRT(O24/(1-O24)) -> 0.0046808313
A25: alpha | B25: 0.05 | J25: =J24+1 -> 22 | K25: =demanda!D23 -> 4 | L25: =demanda!I23 -> 7 | M25: 3.8942745 | N25: =L25-M25 -> 3.1057255 | O25: 0.0024466176 | P25: =N25/SQRT($X$6) -> 0.312925 | Q25: =($X$6-N25^2/((1-O25)*$X$5))*$X$5/($X$5-1) -> 98.548442 | R25: =N25/SQRT(Q25*(1-O25)) -> 0.31323488 | S25: =_xlfn.T.DIST.2T(ABS(R25),$X$5) -> 0.75413626 | T25: =(N25^2/$X$6)*(O25/(1-O25)^2)/($X$7+1) -> 0.00012037722 | U25: =R25*SQRT(O25/(1-O25)) -> 0.015512617
A26: normal | B26: =IF(B24<B25,"no","yes") -> no | J26: =J25+1 -> 23 | K26: =demanda!D24 -> 2 | L26: =demanda!I24 -> 10 | M26: 9.1555419 | N26: =L26-M26 -> 0.8444581 | O26: 0.0007314491 | P26: =N26/SQRT($X$6) -> 0.08508545 | Q26: =($X$6-N26^2/((1-O26)*$X$5))*$X$5/($X$5-1) -> 98.553112 | R26: =N26/SQRT(Q26*(1-O26)) -> 0.085094566 | S26: =_xlfn.T.DIST.2T(ABS(R26),$X$5) -> 0.93219509 | T26: =(N26^2/$X$6)*(O26/(1-O26)^2)/($X$7+1) -> 2.6515528e-06 | U26: =R26*SQRT(O26/(1-O26)) -> 0.0023022515
J27: =J26+1 -> 24 | K27: =demanda!D25 -> 0 | L27: =demanda!I25 -> 12 | M27: 14.416809 | N27: =L27-M27 -> -2.4168093 | O27: 0.00074087557 | P27: =N27/SQRT($X$6) -> -0.24351156 | Q27: =($X$6-N27^2/((1-O27)*$X$5))*$X$5/($X$5-1) -> 98.550436 | R27: =N27/SQRT(Q27*(1-O27)) -> -0.2435421 | S27: =_xlfn.T.DIST.2T(ABS(R27),$X$5) -> 0.80761151 | T27: =(N27^2/$X$6)*(O27/(1-O27)^2)/($X$7+1) -> 2.1998759e-05 | U27: =R27*SQRT(O27/(1-O27)) -> -0.0066314366
A28: d'Agostino-Pearson | J28: =J27+1 -> 25 | K28: =demanda!D26 -> 0 | L28: =demanda!I26 -> 35 | M28: 14.416809 | N28: =L28-M28 -> 20.583191 | O28: 0.00074087557 | P28: =N28/SQRT($X$6) -> 2.0739099 | Q28: =($X$6-N28^2/((1-O28)*$X$5))*$X$5/($X$5-1) -> 98.33243 | R28: =N28/SQRT(Q28*(1-O28)) -> 2.076468 | S28: =_xlfn.T.DIST.2T(ABS(R28),$X$5) -> 0.037983496 | T28: =(N28^2/$X$6)*(O28/(1-O28)^2)/($X$7+1) -> 0.0015956544 | U28: =R28*SQRT(O28/(1-O28)) -> 0.056540394
J29: =J28+1 -> 26 | K29: =demanda!D27 -> 4 | L29: =demanda!I27 -> 4 | M29: 3.8942745 | N29: =L29-M29 -> 0.10572548 | O29: 0.0024466176 | P29: =N29/SQRT($X$6) -> 0.01065263 | Q29: =($X$6-N29^2/((1-O29)*$X$5))*$X$5/($X$5-1) -> 98.553478 | R29: =N29/SQRT(Q29*(1-O29)) -> 0.010662907 | S29: =_xlfn.T.DIST.2T(ABS(R29),$X$5) -> 0.9914935 | T29: =(N29^2/$X$6)*(O29/(1-O29)^2)/($X$7+1) -> 1.3950107e-07 | U29: =R29*SQRT(O29/(1-O29)) -> 0.0005280689
A30: DA-stat | B30: =[1]!DAGOSTINO(N4:N1924) -> 1556.0928 | J30: =J29+1 -> 27 | K30: =demanda!D28 -> 4 | L30: =demanda!I28 -> 3 | M30: 3.8942745 | N30: =L30-M30 -> -0.89427452 | O30: 0.0024466176 | P30: =N30/SQRT($X$6) -> -0.090104826 | Q30: =($X$6-N30^2/((1-O30)*$X$5))*$X$5/($X$5-1) -> 98.553066 | R30: =N30/SQRT(Q30*(1-O30)) -> -0.090191937 | S30: =_xlfn.T.DIST.2T(ABS(R30),$X$5) -> 0.9281441 | T30: =(N30^2/$X$6)*(O30/(1-O30)^2)/($X$7+1) -> 9.9806749e-06 | U30: =R30*SQRT(O30/(1-O30)) -> -0.0044666579
A31: p-value | B31: =[1]!DPTEST(N4:N1924) -> 0 | J31: =J30+1 -> 28 | K31: =demanda!D29 -> 2 | L31: =demanda!I29 -> 3 | M31: 9.1555419 | N31: =L31-M31 -> -6.1555419 | O31: 0.0007314491 | P31: =N31/SQRT($X$6) -> -0.62021675 | Q31: =($X$6-N31^2/((1-O31)*$X$5))*$X$5/($X$5-1) -> 98.533714 | R31: =N31/SQRT(Q31*(1-O31)) -> -0.62034424 | S31: =_xlfn.T.DIST.2T(ABS(R31),$X$5) -> 0.53510483 | T31: =(N31^2/$X$6)*(O31/(1-O31)^2)/($X$7+1) -> 0.00014088886 | U31: =R31*SQRT(O31/(1-O31)) -> -0.016783545
A32: alpha | B32: 0.05 | J32: =J31+1 -> 29 | K32: =demanda!D30 -> 5 | L32: =demanda!I30 -> 3 | M32: 1.2636408 | N32: =L32-M32 -> 1.7363592 | O32: 0.0039509249 | P32: =N32/SQRT($X$6) -> 0.17495113 | Q32: =($X$6-N32^2/((1-O32)*$X$5))*$X$5/($X$5-1) -> 98.551906 | R32: =N32/SQRT(Q32*(1-O32)) -> 0.17525349 | S32: =_xlfn.T.DIST.2T(ABS(R32),$X$5) -> 0.86089894 | T32: =(N32^2/$X$6)*(O32/(1-O32)^2)/($X$7+1) -> 6.0945385e-05 | U32: =R32*SQRT(O32/(1-O32)) -> 0.011037627
A33: normal | B33: =IF(B31<B32,"no","yes") -> no | J33: =J32+1 -> 30 | K33: =demanda!D31 -> 4 | L33: =demanda!I31 -> 2 | M33: 3.8942745 | N33: =L33-M33 -> -1.8942745 | O33: 0.0024466176 | P33: =N33/SQRT($X$6) -> -0.19086228 | Q33: =($X$6-N33^2/((1-O33)*$X$5))*$X$5/($X$5-1) -> 98.551608 | R33: =N33/SQRT(Q33*(1-O33)) -> -0.19104822 | S33: =_xlfn.T.DIST.2T(ABS(R33),$X$5) -> 0.84850803 | T33: =(N33^2/$X$6)*(O33/(1-O33)^2)/($X$7+1) -> 4.4782056e-05 | U33: =R33*SQRT(O33/(1-O33)) -> -0.0094614557
J34: =J33+1 -> 31 | K34: =demanda!D32 -> 0 | L34: =demanda!I32 -> 21 | M34: 14.416809 | N34: =L34-M34 -> 6.5831907 | O34: 0.00074087557 | P34: =N34/SQRT($X$6) -> 0.66330555 | Q34: =($X$6-N34^2/((1-O34)*$X$5))*$X$5/($X$5-1) -> 98.530871 | R34: =N34/SQRT(Q34*(1-O34)) -> 0.66345461 | S34: =_xlfn.T.DIST.2T(ABS(R34),$X$5) -> 0.50711913 | T34: =(N34^2/$X$6)*(O34/(1-O34)^2)/($X$7+1) -> 0.00016322486 | U34: =R34*SQRT(O34/(1-O34)) -> 0.018065284
J35: =J34+1 -> 32 | K35: =demanda!D33 -> 2 | L35: =demanda!I33 -> 5 | M35: 9.1555419 | N35: =L35-M35 -> -4.1555419 | O35: 0.0007314491 | P35: =N35/SQRT($X$6) -> -0.41870183 | Q35: =($X$6-N35^2/((1-O35)*$X$5))*$X$5/($X$5-1) -> 98.544474 | R35: =N35/SQRT(Q35*(1-O35)) -> -0.41876504 | S35: =_xlfn.T.DIST.2T(ABS(R35),$X$5) -> 0.67543472 | T35: =(N35^2/$X$6)*(O35/(1-O35)^2)/($X$7+1) -> 6.4209516e-05 | U35: =R35*SQRT(O35/(1-O35)) -> -0.011329777
J36: =J35+1 -> 33 | K36: =demanda!D34 -> 5 | L36: =demanda!I34 -> 2 | M36: 1.2636408 | N36: =L36-M36 -> 0.73635917 | O36: 0.0039509249 | P36: =N36/SQRT($X$6) -> 0.074193677 | Q36: =($X$6-N36^2/((1-O36)*$X$5))*$X$5/($X$5-1) -> 98.5532 | R36: =N36/SQRT(Q36*(1-O36)) -> 0.074321414 | S36: =_xlfn.T.DIST.2T(ABS(R36),$X$5) -> 0.94076238 | T36: =(N36^2/$X$6)*(O36/(1-O36)^2)/($X$7+1) -> 1.0960771e-05 | U36: =R36*SQRT(O36/(1-O36)) -> 0.0046808313
J37: =J36+1 -> 34 | K37: =demanda!D35 -> 3 | L37: =demanda!I35 -> 9 | M37: 6.5249082 | N37: =L37-M37 -> 2.4750918 | O37: 0.001373459 | P37: =N37/SQRT($X$6) -> 0.24938395 | Q37: =($X$6-N37^2/((1-O37)*$X$5))*$X$5/($X$5-1) -> 98.550285 | R37: =N37/SQRT(Q37*(1-O37)) -> 0.24949441 | S37: =_xlfn.T.DIST.2T(ABS(R37),$X$5) -> 0.80300507 | T37: =(N37^2/$X$6)*(O37/(1-O37)^2)/($X$7+1) -> 4.2826886e-05 | U37: =R37*SQRT(O37/(1-O37)) -> 0.0092526707
J38: =J37+1 -> 35 | K38: =demanda!D36 -> 2 | L38: =demanda!I36 -> 21 | M38: 9.1555419 | N38: =L38-M38 -> 11.844458 | O38: 0.0007314491 | P38: =N38/SQRT($X$6) -> 1.1934175 | Q38: =($X$6-N38^2/((1-O38)*$X$5))*$X$5/($X$5-1) -> 98.480286 | R38: =N38/SQRT(Q38*(1-O38)) -> 1.1939866 | S38: =_xlfn.T.DIST.2T(ABS(R38),$X$5) -> 0.2326308 | T38: =(N38^2/$X$6)*(O38/(1-O38)^2)/($X$7+1) -> 0.00052164429 | U38: =R38*SQRT(O38/(1-O38)) -> 0.03230356
J39: =J38+1 -> 36 | K39: =demanda!D37 -> 0 | L39: =demanda!I37 -> 16 | M39: 14.416809 | N39: =L39-M39 -> 1.5831907 | O39: 0.00074087557 | P39: =N39/SQRT($X$6) -> 0.15951827 | Q39: =($X$6-N39^2/((1-O39)*$X$5))*$X$5/($X$5-1) -> 98.552176 | R39: =N39/SQRT(Q39*(1-O39)) -> 0.15953687 | S39: =_xlfn.T.DIST.2T(ABS(R39),$X$5) -> 0.8732627 | T39: =(N39^2/$X$6)*(O39/(1-O39)^2)/($X$7+1) -> 9.4401718e-06 | U39: =R39*SQRT(O39/(1-O39)) -> 0.0043440483
J40: =J39+1 -> 37 | K40: =demanda!D38 -> 0 | L40: =demanda!I38 -> 21 | M40: 14.416809 | N40: =L40-M40 -> 6.5831907 | O40: 0.00074087557 | P40: =N40/SQRT($X$6) -> 0.66330555 | Q40: =($X$6-N40^2/((1-O40)*$X$5))*$X$5/($X$5-1) -> 98.530871 | R40: =N40/SQRT(Q40*(1-O40)) -> 0.66345461 | S40: =_xlfn.T.DIST.2T(ABS(R40),$X$5) -> 0.50711913 | T40: =(N40^2/$X$6)*(O40/(1-O40)^2)/($X$7+1) -> 0.00016322486 | U40: =R40*SQRT(O40/(1-O40)) -> 0.018065284
J41: =J40+1 -> 38 | K41: =demanda!D39 -> 0 | L41: =demanda!I39 -> 49 | M41: 14.416809 | N41: =L41-M41 -> 34.583191 | O41: 0.00074087557 | P41: =N41/SQRT($X$6) -> 3.4845143 | Q41: =($X$6-N41^2/((1-O41)*$X$5))*$X$5/($X$5-1) -> 97.929457 | R41: =N41/SQRT(Q41*(1-O41)) -> 3.4959831 | S41: =_xlfn.T.DIST.2T(ABS(R41),$X$5) -> 0.00048305417 | T41: =(N41^2/$X$6)*(O41/(1-O41)^2)/($X$7+1) -> 0.0045044684 | U41: =R41*SQRT(O41/(1-O41)) -> 0.095192537
...

Sheet demanda
A1: fecha | B1: hora | C1: ruta | D1: alumnos_esperando | E1: llegadas_intervalo | F1: hora_salida | G1: pasajeros_al_salir | H1: tipo_salida | I1: tiempo_espera_acum | J1: tiempo_recorrido | K1: paradas_intermedias | L1: alumnos_recogidos_intermedias | M1: total_pasajeros_final | N1: hora_llegada_upp
A2: 2026-08-01 | B2: 06:00 | C2: Las vías | D2: 0 | E2: 23 | F2: 06:03 | G2: 18 | H2: Llena | I2: 3 | J2: 29.4 | K2: 2 | L2: 4 | M2: 22 | N2: 06:32
A3: 2026-08-01 | B3: 06:04 | C3: Las vías | D3: 5 | E3: 14 | F3: 06:06 | G3: 18 | H3: Llena | I3: 2 | J3: 28.5 | K3: 0 | L3: 0 | M3: 18 | N3: 06:34
A4: 2026-08-01 | B4: 06:07 | C4: Las vías | D4: 1 | E4: 17 | F4: 06:10 | G4: 18 | H4: Llena | I4: 3 | J4: 27.7 | K4: 1 | L4: 4 | M4: 22 | N4: 06:37
A5: 2026-08-01 | B5: 06:11 | C5: Las vías | D5: 0 | E5: 20 | F5: 06:16 | G5: 18 | H5: Llena | I5: 5 | J5: 25.8 | K5: 2 | L5: 2 | M5: 20 | N5: 06:41
A6: 2026-08-01 | B6: 06:00 | C6: Puente Tuzos | D6: 0 | E6: 18 | F6: 06:16 | G6: 18 | H6: Llena | I6: 16 | J6: 18.9 | K6: 3 | L6: 2 | M6: 20 | N6: 06:34
A7: 2026-08-01 | B7: 06:17 | C7: Las vías | D7: 2 | E7: 19 | F7: 06:20 | G7: 18 | H7: Llena | I7: 3 | J7: 31.9 | K7: 3 | L7: 4 | M7: 22 | N7: 06:51
A8: 2026-08-01 | B8: 06:21 | C8: Las vías | D8: 3 | E8: 17 | F8: 06:25 | G8: 18 | H8: Llena | I8: 4 | J8: 28 | K8: 2 | L8: 3 | M8: 21 | N8: 06:53
A9: 2026-08-01 | B9: 06:17 | C9: Puente Tuzos | D9: 0 | E9: 18 | F9: 06:27 | G9: 18 | H9: Llena | I9: 10 | J9: 22.1 | K9: 4 | L9: 3 | M9: 21 | N9: 06:49
A10: 2026-08-01 | B10: 06:26 | C10: Las vías | D10: 2 | E10: 17 | F10: 06:29 | G10: 18 | H10: Llena | I10: 3 | J10: 26.9 | K10: 3 | L10: 3 | M10: 21 | N10: 06:55
A11: 2026-08-01 | B11: 06:30 | C11: Las vías | D11: 1 | E11: 17 | F11: 06:47 | G11: 18 | H11: Llena | I11: 17 | J11: 26.2 | K11: 2 | L11: 3 | M11: 21 | N11: 07:13
A12: 2026-08-01 | B12: 06:48 | C12: Las vías | D12: 0 | E12: 18 | F12: 06:57 | G12: 18 | H12: Llena | I12: 9 | J12: 26.9 | K12: 3 | L12: 3 | M12: 21 | N12: 07:23
A13: 2026-08-01 | B13: 06:58 | C13: Las vías | D13: 0 | E13: 20 | F13: 07:03 | G13: 18 | H13: Llena | I13: 5 | J13: 24.6 | K13: 0 | L13: 0 | M13: 18 | N13: 07:27
... A1922: 2026-08-21 | B1922: 18:13 | C1922: Las vías | D1922: 0 | E1922: 11 | F1922: 18:28 | G1922: 11 | H1922: Parcial | I1922: 15 | J1922: 27.5 | K1922: 4 | L1922: 3 | M1922: 14 | N1922: 18:55
